<?xml version="1.0"?>
<robot name="box">
    <link name="body">
        <!-- base -->
        <visual>
            <origin rpy="0 0 0" xyz="0 0 0.01"/>
            <geometry>
                <box size="0.25 0.25 0.02"/>
            </geometry>
            <material name="blue">
                <color rgba="0 0 1 0.5" />
            </material>
        </visual>
        <!-- front -->
        <visual>
            <origin rpy="0 0 0" xyz="0.115 0 0.125"/>
            <geometry>
                <box size="0.02 0.25 0.25"/>
            </geometry>
            <material name="blue">
                <color rgba="0 0 1 0.5" />
            </material>
        </visual>
        <!-- back -->
        <visual>
            <origin rpy="0 0 0" xyz="-0.115 0 0.125"/>
            <geometry>
                <box size="0.02 0.25 0.25"/>
            </geometry>
            <material name="blue">
                <color rgba="0 0 1 0.5" />
            </material>
        </visual>
        <!-- left -->
        <visual>
            <origin rpy="0 0 0" xyz="0 0.115 0.125"/>
            <geometry>
                <box size="0.25 0.02 0.25"/>
            </geometry>
            <material name="blue">
                <color rgba="0 0 1 0.5" />
            </material>
        </visual>
        <!-- right -->
        <visual>
            <origin rpy="0 0 0" xyz="0 -0.115 0.125"/>
            <geometry>
                <box size="0.25 0.02 0.25"/>
            </geometry>
            <material name="blue">
                <color rgba="0 0 1 0.5" />
            </material>
        </visual>


        <collision>
            <origin rpy="0 0 0" xyz="0 0 0.01" />
            <geometry>
              <box size="0.25 0.25 0.02" />
            </geometry>
        </collision>
        <collision>
            <origin rpy="0 0 0" xyz="0.115 0 0.125"/>
            <geometry>
                <box size="0.02 0.25 0.25"/>
            </geometry>
        </collision>
        
        <collision>
            <origin rpy="0 0 0" xyz="-0.115 0 0.125"/>
            <geometry>
                <box size="0.02 0.25 0.25"/>
            </geometry>
        </collision>
        
        <collision>
            <origin rpy="0 0 0" xyz="0 0.115 0.125"/>
            <geometry>
                <box size="0.25 0.02 0.25"/>
            </geometry>
        </collision>
        
        <collision>
            <origin rpy="0 0 0" xyz="0 -0.115 0.125"/>
            <geometry>
                <box size="0.25 0.02 0.25"/>
            </geometry>
        </collision>
    </link>
    <link name="door">
        <visual>
            <origin rpy="0 0 0" xyz="0 -0.105 0"/>
            <geometry>
                <box size="0.20 0.20 0.02"/>
            </geometry>
            <material name="cyan">
                <color rgba="0 1 1 0.8" />
            </material>
        </visual>
        <visual>
            <origin rpy="0 0 0" xyz="0 -0.18 0.04"/>
            <geometry>
                <box size="0.08 0.02 0.02"/>
            </geometry>
            <material name="purple">
                <color rgba="1 1 0 1" />
            </material>
        </visual>
        <visual>
            <origin rpy="0 0 0" xyz="0.03 -0.18 0.02"/>
            <geometry>
                <box size="0.02 0.02 0.04"/>
            </geometry>
            <material name="purple">
                <color rgba="1 1 0 1" />
            </material>
        </visual>
        <visual>
            <origin rpy="0 0 0" xyz="-0.03 -0.18 0.02"/>
            <geometry>
                <box size="0.02 0.02 0.04"/>
            </geometry>
            <material name="purple">
                <color rgba="1 1 0 1" />
            </material>
        </visual>
        <collision>
            <origin rpy="0 0 0" xyz="0 -0.105 0"/>
            <geometry>
                <box size="0.21 0.21 0.02"/>
            </geometry>
        </collision>
        <collision>
            <origin rpy="0 0 0" xyz="0 -0.18 0.04"/>
            <geometry>
                <box size="0.08 0.02 0.02"/>
            </geometry>
        </collision>
        <inertial>
            <origin rpy="0 0 0" xyz="0 -0.105 0"/>
            <mass value="0.1" />
            <inertia ixx="0.1" ixy="0" ixz="0" iyy="0.1" iyz="0" izz="0.1" />
        </inertial>
    </link>
    <joint name="joint1" type="revolute">
        <parent link="body" />
        <child link="door" />
        <dynamics damping="1.0" friction="0.01" />
        <origin xyz="0 0.105 0.25" />
        <axis xyz="-1 0 0" />
        <limit lower="0" upper="2.2" effort="10" velocity="0.1"/>
    </joint> 
</robot>