<?xml version="1.0" ?>
<robot name="door">
  <link name="base_link" />
  <link name="doorFrameLink1">
    <contact>
      <lateral_friction value="10.0"/>
      <rolling_friction value="0.0"/>
      <contact_cfm value="0.0"/>
      <contact_erp value="0.0"/>
    </contact>
    <inertial>
      <origin rpy="0 0 0" xyz="0 0 0"/>
       <mass value="1"/>
       <inertia ixx="1" ixy="0" ixz="0" iyy="1" iyz="0" izz="1"/>
    </inertial>
    <visual>
      <origin rpy="0 0 0" xyz="0 0 0"/>
      <geometry>
				<mesh filename="meshes/cube.obj" scale="0.05 0.4 0.05"/>
      </geometry>
       <material name="black">
        <color rgba="0 0 0 1"/>
      </material>
    </visual>
    <collision>
      <!-- <contact_coefficients mu='10.0' kp='100.0' kd='1.0'/> -->
      <origin rpy="0 0 0" xyz="0 0 0"/>
      <geometry>
	 	<box size="0.05 0.4 0.05"/>
      </geometry>
    </collision>
  </link>
  <joint name="joint1" type="fixed">
    <parent link="base_link"/>
    <child link="doorFrameLink1"/>
    <origin xyz="0 -0.3 0.025" rpy="0 0 0"/>
  </joint>

  <link name="doorFrameLink2">
    <contact>
      <lateral_friction value="10.0"/>
      <rolling_friction value="0.0"/>
      <contact_cfm value="0.0"/>
      <contact_erp value="0.0"/>
    </contact>
    <inertial>
      <origin rpy="0 0 0" xyz="0 0 0"/>
       <mass value="1"/>
       <inertia ixx="1" ixy="0" ixz="0" iyy="1" iyz="0" izz="1"/>
    </inertial>
    <visual>
      <origin rpy="0 0 0" xyz="0 0 0"/>
      <geometry>
				<mesh filename="meshes/cube.obj" scale="0.05 0.4 0.05"/>
      </geometry>
       <material name="black">
        <color rgba="0 0 0 1"/>
      </material>
    </visual>
    <collision>
      <origin rpy="0 0 0" xyz="0 0 0"/>
      <geometry>
        <box size="0.05 0.4 0.05"/>
      </geometry>
    </collision>
  </link>
  <joint name="joint2" type="fixed">
    <parent link="base_link"/>
    <child link="doorFrameLink2"/>
    <origin xyz="0 0.3 0.025" rpy="0 0 0"/>
  </joint>

  <link name="doorLink">
    <contact>
      <lateral_friction value="10.0"/>
      <rolling_friction value="0.0"/>
      <contact_cfm value="0.0"/>
      <contact_erp value="0.0"/>
    </contact>
    <inertial>
      <origin rpy="0 0 0" xyz="0 0 0"/>
       <mass value="1"/>
       <inertia ixx="1" ixy="0" ixz="0" iyy="1" iyz="0" izz="1"/>
    </inertial>
    <visual>
      <origin rpy="0 0 0" xyz="0 0 0"/>
      <geometry>
				<mesh filename="meshes/cube.obj" scale="0.05 0.4 0.05"/>
      </geometry>
       <material name="white">
        <color rgba="1 1 1 1"/>
      </material>
    </visual>
    <collision>
      <!-- <contact_coefficients mu='10.0' kp='100.0' kd='1.0'/> -->
      <origin rpy="0 0 0" xyz="0 0 0"/>
      <geometry>
        <box size="0.05 0.4 0.05"/>
      </geometry>
    </collision>
  </link>
  <joint name="joint3" type="prismatic">
    <parent link="base_link"/>
    <child link="doorLink"/>
    <origin xyz="0.05 0 0.025" rpy="0 0 0"/>
    <axis xyz="0 1 0"/>
    <dynamics damping="1.0" friction="1.0"/>
    <limit lower="-0.3" upper="0.3" effort="10" velocity="0.1"/>
  </joint>
</robot>

